File: inst/extdata/20170620_BITHERMAL_SF_VSM_SF20170517SI2_MVSH_3K.DAT
[Header]
; VSM Data File (default extension .dat)
; Copyright (c) 2003, Quantum Design, Inc. All rights reserved.
TITLE,SAMPLE S4 M VS H AT 3 KELVIN
FILEOPENTIME,2827018.81,06/20/2017,5:24 pm
BYAPP,VSM,1.0,1.0
INFO,PPMS VSM Option Release 1.3.7 Build 2,APPNAME
INFO,171,COIL_SERIAL_NUMBER
INFO,0,MOMENT_UNITS
INFO,FePc,SAMPLE_MATERIAL
INFO,SF20170517 S4,SAMPLE_COMMENT
INFO,,SAMPLE_MASS
INFO,,SAMPLE_VOLUME
INFO,,SAMPLE_MOLECULAR_WEIGHT
INFO,,SAMPLE_SIZE
INFO,,SAMPLE_SHAPE
INFO,35.03,SAMPLE_OFFSET
DATATYPE,COMMENT,1
DATATYPE,TIME,2
STARTUPAXIS,X,2
STARTUPAXIS,Y1,5
[Data]
Comment,Time Stamp (sec),Temperature (K),Magnetic Field (Oe),Moment (emu),M. Std. Err. (emu),Transport Action,Averaging Time (sec),Frequency (Hz),Peak Amplitude (mm),Center Position (mm),Coil Signal' (mV),Coil Signal" (mV),Range (mV),M. Quad. Signal (emu),M. Raw' (emu),M. Raw" (emu),Min. Temperature (K),Max. Temperature (K),Min. Field (Oe),Max. Field (Oe),Mass (grams),Motor Lag (deg),Pressure (Torr),VSM Status (code),Motor Status (code),Measure Status (code),PPMS Status (code),System Temp. (K),System Field (Oe),Sample Position (deg),Bridge 1 Resistance (ohms),Bridge 1 Excitation (에),Bridge 2 Resistance (ohms),Bridge 2 Excitation (에),Bridge 3 Resistance (ohms),Bridge 3 Excitation (에),Bridge 4 Resistance (ohms),Bridge 4 Excitation (에),Signal 1 Vin (V),Signal 2 Vin (V),Digital Inputs (code),Drive 1 Iout (mA),Drive 1 Ipower (W),Drive 2 Iout (mA),Drive 2 Ipower (W),Pressure (),Map 20 (),Map 21 (),Map 22 (),Map 23 (),Map 24 (),Map 25 (),Map 26 (),Map 27 (),Map 28 (),Map 29 ()
,2827301.42,2.998965,0.061,,,2,,,,9.29000184491277,,,,,,,2.998965,2.998965,0.061,0.061,,,,,,,4881,3.0021,0.061,,,,,,,,,,,,,,,,,13.022443,,,,,,2.998965,,,,
,2827477.015,3.003945,19517.4085,-9.65011699127241E-6,8.65218655613165E-7,1,0.999253354069792,40.0298881530762,1.9801447652958,9.28000226616859,-0.000105258465143468,-3.55613481665422E-5,0.25,-1.42232356626426E-6,-9.59490065256605E-6,-1.47494229590494E-6,3.0009592,3.0069308,19462.465,19572.352,51.4030179386978,18.3280592043163,0.6047974,0,0,0,4961,2.9902,19517.4085,,,,,,,,,,,,,,,,,12.644608,,,,,,3.003945,,,,
,2827484.775,3.0017557,18605.046,-4.15246493959003E-6,9.01641549241199E-7,1,0.999253354069792,40.0298881530762,1.98022928231065,9.29000187665224,-4.19731050814186E-5,-3.3596973424268E-5,0.25,-2.24481870186852E-6,-4.11841506461093E-6,-2.25915450514779E-6,3.0017557,3.0017557,18582.035,18628.057,51.5179173310247,18.3337732019545,0.6047974,0,0,0,4961,2.9935,18605.046,,,,,,,,,,,,,,,,,13.022443,,,,,,3.0017557,,,,
,2827492.355,3.0024413,17772.613,-2.40695894481137E-7,1.66323883875709E-7,1,0.999253354069792,40.0298881530762,1.98016731407194,9.28000226616859,1.97336987376103E-6,-2.62495544394363E-5,0.25,-2.29889207153587E-6,-2.25597879215336E-7,-2.28889837238286E-6,3.0023432,3.0025394,17761.529,17783.697,51.6789328059862,18.3306319022895,0.610839,0,0,0,4961,2.994,17772.613,,,,,,,,,,,,,,,,,12.644608,,,,,,3.0024413,,,,
,2827500.105,3.001515,16950.416,5.21772367840769E-6,4.39001872004629E-7,1,0.999253354069792,40.0298881530762,1.98025526002202,9.28000226616859,6.30767740137032E-5,-1.48395207199901E-5,0.25,-2.27002246125668E-6,5.20493357279699E-6,-2.22728778225512E-6,3.0014889,3.0015411,16883.355,17017.477,51.5937352973901,18.3340128509614,0.610839,0,0,0,4961,2.9941,16950.416,,,,,,,,,,,,,,,,,13.400279,,,,,,3.001515,,,,
,2827507.275,3.0003909,16186.546,8.45878611922078E-6,5.16911841278739E-7,1,0.999253354069792,40.0298881530762,1.98030079975362,9.28000226616859,9.94733540430995E-5,-8.72886413516641E-6,0.25,-2.31169477965693E-6,8.42913398098329E-6,-2.24961798225719E-6,3.0002527,3.0005291,16123.524,16249.568,51.5116643028708,18.334611780802,0.6139054,0,0,0,4961,2.9945,16186.546,,,,,,,,,,,,,,,,,13.022443,,,,,,3.0003909,,,,
,2827515.82,3.0003722,15295.317,1.30764183685788E-5,5.50580612340755E-7,1,0.999253354069792,40.0298881530762,1.98020833184484,9.28000226616859,0.00015095732526356,1.944776481897E-6,0.25,-2.19493250476764E-6,1.30211913773985E-5,-2.10667519294421E-6,3.0003722,3.0003722,15274.09,15316.544,51.6633002356016,18.3336216089564,0.6047974,0,0,0,4961,2.994,15295.317,,,,,,,,,,,,,,,,,12.644608,,,,,,3.0003722,,,,
,2827523.58,2.9999816,14478.096,1.67577799709223E-5,5.53190706856081E-7,1,0.999253354069792,40.0298881530762,1.98034768017061,9.28000226616859,0.000191143404492436,1.52469123211608E-5,0.25,-1.67343255870056E-6,1.66789810975231E-5,-1.56711162706994E-6,2.9999816,2.9999816,14468.232,14487.96,52.1072652345247,18.3370708821529,0.6169718,0,0,0,4961,2.99415,14478.096,,,,,,,,,,,,,,,,,13.400279,,,,,,2.9999816,,,,
,2827530.83,2.9993517,13707.56,2.18610438665457E-5,5.42363195060285E-7,1,0.999253354069792,40.0298881530762,1.98022659789031,9.28000226616859,0.000248748114932468,2.30414717807126E-5,0.25,-1.90027450249615E-6,2.17550042270561E-5,-1.76414541910313E-6,2.9993517,2.9993517,13682.859,13732.261,51.7922689412747,18.3357756508342,0.6169718,0,0,0,4961,2.9953,13707.56,,,,,,,,,,,,,,,,,13.022443,,,,,,2.9993517,,,,
,2827538.085,2.9998206,12936.0895,2.60783182038991E-5,4.94428349376777E-7,1,0.999253354069792,40.0298881530762,1.98022442972116,9.29000187665224,0.000295966047321211,3.16114207734537E-5,0.25,-1.89697423219877E-6,2.59478275145488E-5,-1.73788859752569E-6,2.9998059,2.9998353,12883.588,12988.591,51.4514789068901,18.3373734679529,0.610839,0,0,0,4961,2.99525,12936.0895,,,,,,,,,,,,,,,,,13.400279,,,,,,2.9998206,,,,
,2827546.755,2.9997356,12024.853,3.03208683596256E-5,5.47389466517418E-7,1,0.999253354069792,40.0298881530762,1.9802798259888,9.28000226616859,0.000343547008945696,3.97860347316546E-5,0.25,-1.93270166378921E-6,3.01650921092373E-5,-1.7510743837956E-6,2.9997356,2.9997356,12014.052,12035.654,51.6976918904478,18.3357848607432,0.6169718,0,0,0,4961,2.9951,12024.853,,,,,,,,,,,,,,,,,13.400279,,,,,,2.9997356,,,,
,2827554.44,2.9994867,11228.8575,3.36167017215606E-5,5.62256140011051E-7,1,0.999253354069792,40.0298881530762,1.98022948216613,9.28000226616859,0.00038028665808616,4.72406873625118E-5,0.25,-1.86098333004142E-6,3.34400422458156E-5,-1.66299917304948E-6,2.9994867,2.9994867,11207.819,11249.896,51.4569503065247,18.3367181872972,0.610839,0,0,0,4961,2.9945,11228.8575,,,,,,,,,,,,,,,,,12.644608,,,,,,2.9994867,,,,
,2827562.115,2.99811355,10420.936,3.7725289738772E-5,4.65502211230327E-7,1,0.999253354069792,40.0298881530762,1.98024526180977,9.28000226616859,0.000426621144359143,5.36570902195784E-5,0.25,-2.02849645332258E-6,3.75240674701E-5,-1.80875769994971E-6,2.9981015,2.9981256,10420.936,10420.936,51.4889970758131,18.3338416432064,0.610839,0,0,0,4961,2.9955,10420.936,,,,,,,,,,,,,,,,,13.400279,,,,,,2.99811355,,,,
,2827568.565,2.99922265,9751.5495,4.16570706659217E-5,5.0564503718661E-7,1,0.999253354069792,40.0298881530762,1.98028821386051,9.28000226616859,0.000468874892652764,7.1377873273164E-5,0.25,-1.15469531796819E-6,4.1426568506862E-5,-9.20162546418066E-7,2.9988427,2.9996026,9685.522,9817.577,51.6406330085439,18.3376901868046,0.6139054,0,0,0,4961,2.99585,9751.5495,,,,,,,,,,,,,,,,,13.400279,,,,,,2.99922265,,,,
,2827576.645,2.9991152,8887.3655,4.58391924997541E-5,6.01887136162166E-7,1,0.999253354069792,40.0298881530762,1.98028425566249,9.28000226616859,0.000516580793612334,7.48219263241155E-5,0.25,-1.5995208540653E-6,4.55841058382639E-5,-1.3423923170971E-6,2.9991152,2.9991152,8877.222,8897.509,51.7688200856978,18.3367307206132,0.6017615,0,0,0,4961,2.99515,8887.3655,,,,,,,,,,,,,,,,,13.022443,,,,,,2.9991152,,,,
,2827584.765,2.9978576,8037.272,4.98808639635792E-5,4.29738205314165E-7,1,0.999253354069792,40.0298881530762,1.98023635271415,9.29000187665224,0.000562515577796296,7.89785457350473E-5,0.25,-1.95468394847592E-6,4.96010443531278E-5,-1.67665687004393E-6,2.9978576,2.9978576,8026.282,8048.262,51.4264667942747,18.3356076219363,0.6047974,0,0,0,4961,2.9961,8037.272,,,,,,,,,,,,,,,,,13.400279,,,,,,2.9978576,,,,
,2827592.52,2.9981093,7214.131,5.31826778348962E-5,6.65753401046514E-7,1,0.999253354069792,40.0298881530762,1.98027549356981,9.28000226616859,0.000598501669751664,9.09700839155153E-5,0.25,-1.47647279453163E-6,5.28777061254285E-5,-1.18670983388622E-6,2.9981093,2.9981093,7204.082,7224.18,51.5593436425439,18.3392656323517,0.6169718,0,0,0,4961,2.99735,7214.131,,,,,,,,,,,,,,,,,12.644608,,,,,,2.9981093,,,,
,2827600.98,2.9980917,6304.862,5.71171957483495E-5,5.6889674290368E-7,1,0.999253354069792,40.0298881530762,1.98027538359416,9.28000226616859,0.000643449214387544,9.37367872433302E-5,0.25,-1.93526781529825E-6,5.678759474318E-5,-1.62568176906087E-6,2.9980917,2.9980917,6280.067,6329.657,51.6398513800247,18.3363179936284,0.6078638,0,0,0,4961,2.9963,6304.862,,,,,,,,,,,,,,,,,13.400279,,,,,,2.9980917,,,,
,2827608.85,2.99816215,5475.238,6.12734406997726E-5,4.78862556529561E-7,1,0.999253354069792,40.0298881530762,1.98025107338745,9.28000226616859,0.000689966065889353,0.000101961472050026,0.25,-1.94637450710839E-6,6.09154828369005E-5,-1.61859586070426E-6,2.9980423,2.998282,5454.479,5495.997,51.779762884967,18.3384824065033,0.610839,0,0,0,4961,2.9968,5475.238,,,,,,,,,,,,,,,,,13.400279,,,,,,2.99816215,,,,
,2827617.68,2.9982326,4552.255,6.56105569412742E-5,5.2011190974168E-7,1,0.999253354069792,40.0298881530762,1.98027146071143,9.29000187665224,0.000738065224739084,0.000113042893434498,0.25,-1.73413325631597E-6,6.52212448783192E-5,-1.38945701607697E-6,2.9982326,2.9982326,4527.836,4576.674,51.6617369785632,18.3373130696178,0.610839,0,0,0,4961,2.99715,4552.255,,,,,,,,,,,,,,,,,13.400279,,,,,,2.9982326,,,,
,2827625.625,2.9985125,3692.949,6.84236716993545E-5,5.78444788771965E-7,1,0.999253354069792,40.0298881530762,1.98024159771214,9.28000226616859,0.000769201296908951,0.000120396641987193,0.25,-1.57969899773478E-6,6.80126121004953E-5,-1.22563140022391E-6,2.9980099,2.9990151,3625.794,3760.104,51.4725828769093,18.3371070863235,0.6169718,0,0,0,4961,2.99755,3692.949,,,,,,,,,,,,,,,,,13.400279,,,,,,2.9985125,,,,
,2827632.885,2.99839925,2909.72,7.10043611189075E-5,4.26303955515949E-7,1,0.999253354069792,40.0298881530762,1.98027139162065,9.28000226616859,0.000798884565470593,0.000121049523354724,0.25,-1.98243796875158E-6,7.05760110047679E-5,-1.61656636768961E-6,2.9975252,2.9992733,2834.579,2984.861,51.7469344871593,18.3375262996986,0.6139054,0,0,0,4961,2.99685,2909.72,,,,,,,,,,,,,,,,,13.400279,,,,,,2.99839925,,,,
,2827642.025,2.9981065,1934.6025,7.35599345437981E-5,4.63131531914062E-7,1,0.999253354069792,40.0298881530762,1.98037658355876,9.28000226616859,0.000826405681278533,0.000132216546311801,0.25,-1.44077615165388E-6,7.31089248285253E-5,-1.07003955229962E-6,2.9978657,2.9983473,1923.52,1945.685,52.0017453844286,18.3382125856999,0.610839,0,0,0,4961,2.99665,1934.6025,,,,,,,,,,,,,,,,,13.400279,,,,,,2.9981065,,,,
,2827648.86,2.9981197,1203.499,7.25287937601197E-5,4.83430301475913E-7,1,0.999253354069792,40.0298881530762,1.98026640975495,9.28000226616859,0.000816558579837979,0.000120281487102982,0.25,-2.31696093914306E-6,7.20856563006721E-5,-1.94890524340412E-6,2.9976151,2.9986243,1134.37,1272.628,51.6664267496785,18.338593315417,0.6169718,0,0,0,4961,2.9968,1203.499,,,,,,,,,,,,,,,,,13.022443,,,,,,2.9981197,,,,
,2827657.155,2.9985856,270.737,6.40288796812125E-5,5.17952538241022E-7,1,0.999253354069792,40.0298881530762,1.9802832976305,9.28000226616859,0.000720241707796734,0.000109493931669738,0.25,-1.74645375383019E-6,6.36335091210013E-5,-1.42638635775107E-6,2.9981296,2.9990416,249.23,292.244,51.5960801829478,18.3389273465305,0.610839,0,0,0,4961,2.9985,270.737,,,,,,,,,,,,,,,,,12.644608,,,,,,2.9985856,,,,
,2827665.055,2.9963322,-575.6135,-5.37976027563045E-6,6.62664904406489E-7,1,0.999253354069792,40.0298881530762,1.98028514657717,9.28000226616859,-5.62586047108332E-5,-3.2844795776762E-5,0.25,-1.96549744862884E-6,-5.3363827808986E-6,-1.97916855890485E-6,2.9960938,2.9965706,-589.702,-561.525,51.6750246633901,18.3402068281403,0.6169718,0,0,0,4961,2.9944,-575.6135,,,,,,,,,,,,,,,,,12.644608,,,,,,2.9963322,,,,
,2827671.9,2.9986359,-1299.865,-3.40123698476432E-5,5.18156418926614E-7,1,0.999253354069792,40.0298881530762,1.98026472944257,9.28000226616859,-0.000376247231433112,-9.34932503886375E-5,0.25,-2.22637858046546E-6,-3.37885623560881E-5,-2.37841914247171E-6,2.9978616,2.9994102,-1351.241,-1248.489,51.3412692856785,18.3402772929535,0.6169718,0,0,0,4961,2.99815,-1299.865,,,,,,,,,,,,,,,,,13.400279,,,,,,2.9986359,,,,
,2827678.88,2.9988141,-2014.0625,-4.51152072717307E-5,5.30983644615749E-7,1,0.999253354069792,40.0298881530762,1.9802396583917,9.28000226616859,-0.000499891589697641,-0.000119504915388926,0.25,-2.54825390283649E-6,-4.48219031471172E-5,-2.75449246987598E-6,2.9987326,2.9988956,-2064.309,-1963.816,51.8024301120247,18.3380341074749,0.6108695,0,0,0,4961,2.9977,-2014.0625,,,,,,,,,,,,,,,,,12.644608,,,,,,2.9988141,,,,
,2827687.54,2.997206,-2865.861,-5.05277481977678E-5,4.48471455840884E-7,1,0.999253354069792,40.0298881530762,1.98036155382755,9.28000226616859,-0.000561346462711333,-0.00012596196489816,0.25,-2.14604676716452E-6,-5.02050878154877E-5,-2.38430274175037E-6,2.997206,2.997206,-2875.441,-2856.281,51.7610038005055,18.3402988268731,0.6169718,0,0,0,4961,2.9972,-2865.861,,,,,,,,,,,,,,,,,13.400279,,,,,,2.997206,,,,
,2827695.445,2.9998899,-3634.6245,-5.18604763804721E-5,5.30175287467493E-7,1,0.999253354069792,40.0298881530762,1.9802892015918,9.29000187665224,-0.000576326043542845,-0.000128354471396946,0.25,-2.11679085466389E-6,-5.15320590064145E-5,-2.36464048969188E-6,2.9998899,2.9998899,-3643.922,-3625.327,51.4936868469285,18.3408238121256,0.6169718,0,0,0,4961,2.9971,-3634.6245,,,,,,,,,,,,,,,,,13.400279,,,,,,2.9998899,,,,
,2827701.265,2.999336,-4235.4565,-5.21339336976027E-5,7.04417264149368E-7,1,0.999253354069792,40.0298881530762,1.98035626999068,9.28000226616859,-0.000579050494465731,-0.000131010045783474,0.25,-2.30171063651636E-6,-5.18048156330861E-5,-2.55205470923768E-6,2.9991956,2.9994764,-4305.712,-4165.201,51.576539469967,18.3404076404882,0.6108695,0,0,0,4961,2.99825,-4235.4565,,,,,,,,,,,,,,,,,13.400279,,,,,,2.999336,,,,
,2827707.855,2.99888025,-4895.8335,-5.13211583555315E-5,4.13901196133283E-7,1,0.999253354069792,40.0298881530762,1.98032373534805,9.28000226616859,-0.000570729034421141,-0.000125138688440052,0.25,-1.92115441393336E-6,-5.10010717645116E-5,-2.17216449123523E-6,2.9982481,2.9995124,-4959.609,-4832.058,51.7180142319478,18.3404398983373,0.6108695,0,0,0,4961,2.99765,-4895.8335,,,,,,,,,,,,,,,,,12.644608,,,,,,2.99888025,,,,
,2827714.865,2.998486,-5596.5015,-4.96510359845457E-5,4.59850915329366E-7,1,0.999253354069792,40.0298881530762,1.98031156866134,9.28000226616859,-0.000550972272015294,-0.000127757578866367,0.25,-2.45330847037039E-6,-4.93405800378215E-5,-2.69516096319735E-6,2.9983575,2.9986145,-5649.567,-5543.436,51.8188443109286,18.3389614379253,0.6078638,0,0,0,4961,2.99665,-5596.5015,,,,,,,,,,,,,,,,,13.022443,,,,,,2.998486,,,,
,2827720.695,2.99907235,-6208.1295,-4.81394815348841E-5,4.24431465355457E-7,1,0.999253354069792,40.0298881530762,1.98029153709178,9.28000226616859,-0.000535269077478042,-0.000118033579822192,0.25,-1.85504782900642E-6,-4.78431745876028E-5,-2.09488796695439E-6,2.9985359,2.9996088,-6262.887,-6153.372,51.6296902092747,18.3415208786194,0.6047672,0,0,0,4961,2.99775,-6208.1295,,,,,,,,,,,,,,,,,13.400279,,,,,,2.99907235,,,,
,2827728.495,2.9991884,-6988.724,-4.60563536334976E-5,3.70682241683722E-7,1,0.999253354069792,40.0298881530762,1.98038321264011,9.28000226616859,-0.000511093740819259,-0.000118832261855007,0.25,-2.2985775403602E-6,-4.57726126158981E-5,-2.52767506900926E-6,2.9991884,2.9991884,-6999.056,-6978.392,51.8016484835055,18.3405997898709,0.6169718,0,0,0,4961,2.9989,-6988.724,,,,,,,,,,,,,,,,,13.400279,,,,,,2.9991884,,,,
,2827735.82,2.9994669,-7743.679,-4.28796121940052E-5,5.56560307926053E-7,1,0.999253354069792,40.0298881530762,1.98028670092872,9.28000226616859,-0.000475880897444149,-0.000110432888016292,0.25,-2.11946130469161E-6,-4.2617845711478E-5,-2.33537716155922E-6,2.9994669,2.9994669,-7763.591,-7723.767,51.6304718377939,18.3390709385879,0.6169718,0,0,0,4961,2.9982,-7743.679,,,,,,,,,,,,,,,,,13.778115,,,,,,2.9994669,,,,
,2827742.32,2.9993832,-8409.871,-4.05942946964233E-5,2.56543484051012E-7,1,0.999253354069792,40.0298881530762,1.98030886922219,9.29000187665224,-0.000450272488681373,-0.000106063879737383,0.25,-2.13937262907952E-6,-4.0347731351696E-5,-2.34510945731197E-6,2.9993832,2.9993832,-8420.107,-8399.635,51.8079015116593,18.3416743925877,0.6169718,0,0,0,4961,2.9974,-8409.871,,,,,,,,,,,,,,,,,13.400279,,,,,,2.9993832,,,,
,2827750.53,2.9997008,-9249.8215,-3.71691085162571E-5,5.1707287162533E-7,1,0.999253354069792,40.0298881530762,1.9803002229478,9.28000226616859,-0.000412518101124475,-9.59382955871912E-5,0.25,-1.85099843651971E-6,-3.69462540586492E-5,-2.04243044921339E-6,2.9997008,2.9997008,-9270.108,-9229.535,51.7320835452939,18.3399223333629,0.6169718,0,0,0,4961,2.9958,-9249.8215,,,,,,,,,,,,,,,,,13.400279,,,,,,2.9997008,,,,
,2827756.095,3.00048875,-9822.2835,-3.52056180840207E-5,4.84070489513028E-7,1,0.999253354069792,40.0298881530762,1.980248868825,9.28000226616859,-0.000390108660433142,-9.4331175784929E-5,0.25,-2.06060003834273E-6,-3.49943861734646E-5,-2.24174399458295E-6,3.0004761,3.0005014,-9887.56,-9757.007,51.7656935716209,18.3387942452415,0.6169718,0,0,0,4961,2.9971,-9822.2835,,,,,,,,,,,,,,,,,12.644608,,,,,,3.00048875,,,,
,2827764.705,3.0005121,-10718.6775,-3.13725720270826E-5,2.7413328224229E-7,1,0.999253354069792,40.0298881530762,1.98037845443789,9.28000226616859,-0.000347151319831469,-8.70056761149327E-5,0.25,-2.0960850131032E-6,-3.1185065232598E-5,-2.25825970440096E-6,3.0005121,3.0005121,-10739.248,-10698.107,51.9509395306786,18.3414120969059,0.6047672,0,0,0,4961,2.9966,-10718.6775,,,,,,,,,,,,,,,,,13.400279,,,,,,3.0005121,,,,
,2827772.655,3.0008614,-11526.0365,-2.7772298886367E-5,5.4206727497325E-7,1,0.999253354069792,40.0298881530762,1.98035328490518,9.28000226616859,-0.000307171152650331,-7.78952576828887E-5,0.25,-1.93158027954593E-6,-2.76076388635642E-5,-2.076496121643E-6,3.0008614,3.0008614,-11549.8,-11502.273,51.7234856315824,18.3432159555469,0.6169718,0,0,0,4961,2.9961,-11526.0365,,,,,,,,,,,,,,,,,13.400279,,,,,,3.0008614,,,,
,2827780.445,3.0010352,-12344.2905,-2.44583186318971E-5,2.94240642010761E-7,1,0.999253354069792,40.0298881530762,1.98030358795866,9.28000226616859,-0.000269747373342882,-7.29214668574975E-5,0.25,-2.08513368347214E-6,-2.43127271786296E-5,-2.21223820330738E-6,3.0010352,3.0010352,-12354.34,-12334.241,51.5398029295631,18.3410709919786,0.6169718,0,0,0,4961,2.99565,-12344.2905,,,,,,,,,,,,,,,,,12.644608,,,,,,3.0010352,,,,
,2827787.705,3.0010052,-13084.208,-2.17030335840501E-5,5.83487076502011E-7,1,0.999253354069792,40.0298881530762,1.98032936984106,9.28000226616859,-0.000237881813522308,-7.29742073310043E-5,0.25,-2.58665930212146E-6,-2.15709191287445E-5,-2.69674894023011E-6,3.0010052,3.0010052,-13105.153,-13063.263,51.6617369785632,18.3431455898091,0.6169718,0,0,0,4961,2.99535,-13084.208,,,,,,,,,,,,,,,,,13.400279,,,,,,3.0010052,,,,
,2827795.26,3.0006013,-13872.3145,-1.71523195434909E-5,4.47344119779299E-7,1,0.999253354069792,40.0298881530762,1.98030151488667,9.28000226616859,-0.000187167898954537,-6.23374460089492E-5,0.25,-2.45941510457811E-6,-1.70465787943224E-5,-2.54532129904911E-6,3.0005796,3.000623,-13938.248,-13806.381,51.5804476125632,18.3417340342305,0.6047672,0,0,0,4961,2.99475,-13872.3145,,,,,,,,,,,,,,,,,13.400279,,,,,,3.0006013,,,,
,2827802.395,3.00108575,-14609.708,-1.40142006684762E-5,3.29107873795156E-7,1,0.999253354069792,40.0298881530762,1.98021526792906,9.28000226616859,-0.000152051438115519,-5.57679643097819E-5,0.25,-2.44025028163475E-6,-1.3926109314662E-5,-2.50903880096033E-6,3.0009236,3.0012479,-14661.458,-14557.958,52.0126881836978,18.340322920785,0.6139054,0,0,0,4961,2.99535,-14609.708,,,,,,,,,,,,,,,,,13.400279,,,,,,3.00108575,,,,
,2827812.095,3.0021973,-15615.525,-9.79958602127498E-6,5.75729126095978E-7,1,0.999253354069792,40.0298881530762,1.98024594397415,9.28000226616859,-0.000105764738066047,-4.2140974847333E-5,0.25,-1.98599263353148E-6,-9.73710793881783E-6,-2.03349661446035E-6,3.0021973,3.0021973,-15625.67,-15605.38,51.7727282282939,18.3428357746418,0.6169718,0,0,0,4961,2.99585,-15615.525,,,,,,,,,,,,,,,,,13.400279,,,,,,3.0021973,,,,
,2827818.42,3.00250935,-16263.402,-6.21749122728132E-6,4.14943492942806E-7,1,0.999253354069792,40.0298881530762,1.98030875606911,9.29000187665224,-6.60368186575202E-5,-3.26589561837972E-5,0.25,-1.78806726721973E-6,-6.17502564667312E-6,-1.81585880412949E-6,3.0022848,3.0027339,-16328.96,-16197.844,51.7047265471209,18.3416754779457,0.6139054,0,0,0,4961,2.995,-16263.402,,,,,,,,,,,,,,,,,13.400279,,,,,,3.00250935,,,,
,2827825.195,3.002002,-16969.6025,-2.69005852974562E-6,8.34455919745542E-7,1,0.999253354069792,40.0298881530762,1.9803352168563,9.28000226616859,-2.69355594728304E-5,-2.31672192879894E-5,0.25,-1.57985708462752E-6,-2.66699335500407E-6,-1.58798722195167E-6,3.0018008,3.0022032,-17031.309,-16907.896,52.0931959211786,18.3427352224592,0.6047672,0,0,0,4961,2.99435,-16969.6025,,,,,,,,,,,,,,,,,13.400279,,,,,,3.002002,,,,
,2827832.265,3.00279665,-17697.221,8.09737040675959E-7,3.21795488539954E-7,1,0.999253354069792,40.0298881530762,1.98034514055388,9.28000226616859,1.18975905508093E-5,-1.39269942445407E-5,0.25,-1.38956037547536E-6,8.14092933401143E-7,-1.37773858582771E-6,3.0027425,3.0028508,-17742.303,-17652.139,51.5116643028708,18.3446203580952,0.6169718,0,0,0,4961,2.9941,-17697.221,,,,,,,,,,,,,,,,,12.644608,,,,,,3.00279665,,,,
,2827840.165,3.0035241,-18517.4435,5.19704489194202E-6,2.98270284524614E-7,1,0.999253354069792,40.0298881530762,1.98037601268206,9.28000226616859,6.29453815809093E-5,-1.53501754714427E-5,0.25,-2.31215460031648E-6,5.1856248094485E-6,-2.26912115008006E-6,3.0035241,3.0035241,-18527.682,-18507.205,51.9939290992363,18.3443114761519,0.6078638,0,0,0,4961,2.9939,-18517.4435,,,,,,,,,,,,,,,,,13.022443,,,,,,3.0035241,,,,
,2827847.415,3.0030303,-19264.792,8.4971100358814E-6,6.47249230341365E-7,1,0.999253354069792,40.0298881530762,1.98037169805179,9.28000226616859,9.90982254343607E-5,-4.00771469599849E-6,0.25,-1.89901054290793E-6,8.46767186081647E-6,-1.83760356065306E-6,3.002943,3.0031176,-19340.496,-19189.088,51.9954923562747,18.3446253867186,0.6078638,0,0,0,4961,2.9933,-19264.792,,,,,,,,,,,,,,,,,12.644608,,,,,,3.0030303,,,,
,2827855.845,3.000582,-19949.3545,1.24554742067633E-5,3.89386164072003E-7,1,0.999253354069792,40.0298881530762,1.98032927077435,9.28000226616859,0.000143687247373162,2.85351983096515E-6,0.25,-2.00550539912793E-6,1.24084540856174E-5,-1.91883353687428E-6,2.9997709,3.0013931,-19959.84,-19938.869,51.7234856315824,18.3422163289826,0.6139054,0,0,0,4961,2.9916,-19949.3545,,,,,,,,,,,,,,,,,12.644608,,,,,,3.000582,,,,
,2827889.56,3.0005059,-19443.7355,9.47264622640733E-6,3.92676124811855E-7,1,0.999253354069792,40.0298881530762,1.98032931002492,9.28000226616859,0.000109631934542181,1.81413546921084E-7,0.25,-1.70233774348418E-6,9.43746313055438E-6,-1.63580526117533E-6,3.0005059,3.0005059,-19469.846,-19417.625,51.6085862392555,18.3435458652343,0.6169718,0,0,0,4961,2.9903,-19443.7355,,,,,,,,,,,,,,,,,13.400279,,,,,,3.0005059,,,,
,2827897.515,3.0008616,-18498.9715,4.60192144274054E-6,3.31681237170605E-7,1,0.999253354069792,40.0298881530762,1.98031128822026,9.28000226616859,5.61979113707437E-5,-1.61417965515921E-5,0.25,-2.27490058602235E-6,4.59318514514825E-6,-2.23567963921766E-6,3.0008616,3.0008616,-18510.336,-18487.607,51.8196259394478,18.3418964611792,0.6169718,0,0,0,4961,2.9922,-18498.9715,,,,,,,,,,,,,,,,,12.644608,,,,,,3.0008616,,,,
,2827904.33,3.0008851,-17752.1015,4.04153615298366E-7,1.76309180520242E-7,1,0.999253354069792,40.0298881530762,1.98035751811337,9.28000226616859,8.47537690879744E-6,-2.09443109235712E-5,0.25,-1.94218984439124E-6,4.13880014483396E-7,-1.93007058419257E-6,3.0004141,3.0013561,-17783.941,-17720.262,51.5726313273708,18.3430154700551,0.6108695,0,0,0,4961,2.994,-17752.1015,,,,,,,,,,,,,,,,,13.400279,,,,,,3.0008851,,,,
,2827913.165,3.0003457,-16811.281,-4.30367472406925E-6,5.73890496292017E-7,1,0.999253354069792,40.0298881530762,1.98027990983049,9.28000226616859,-4.36970630101442E-5,-3.37194730198667E-5,0.25,-2.22923611744204E-6,-4.26852200479759E-6,-2.24367139916956E-6,3.0003457,3.0003457,-16811.281,-16811.281,51.759440543467,18.3438489820644,0.6047672,0,0,0,4961,2.9943,-16811.281,,,,,,,,,,,,,,,,,13.400279,,,,,,3.0003457,,,,
,2827920.555,3.0012574,-16038.5825,-8.18213210512731E-6,6.56491993779962E-7,1,0.999253354069792,40.0298881530762,1.98029149911823,9.28000226616859,-8.73207578825022E-5,-4.06629466330925E-5,0.25,-2.14662613575001E-6,-8.1273391104516E-6,-2.18408426591971E-6,3.0012574,3.0012574,-16049.572,-16027.593,51.26857783339,18.3421971090669,0.6139054,0,0,0,4961,2.9929,-16038.5825,,,,,,,,,,,,,,,,,13.400279,,,,,,3.0012574,,,,
,2827926.125,3.0002217,-15437.855,-1.18819942792799E-5,4.37852469236461E-7,1,0.999253354069792,40.0298881530762,1.98040355655792,9.28000226616859,-0.000128785323395674,-4.81322225307303E-5,0.25,-2.14337643480341E-6,-1.18076348114729E-5,-2.20216300999178E-6,2.9998574,3.000586,-15501.439,-15374.271,52.0244126114863,18.343175204048,0.62006895,0,0,0,4961,2.99455,-15437.855,,,,,,,,,,,,,,,,,12.644608,,,,,,3.0002217,,,,
,2827934.525,2.99911,-14553.7645,-1.59662282678859E-5,4.51708487476738E-7,1,0.999253354069792,40.0298881530762,1.98045685828946,9.29000187665224,-0.000174348279931423,-5.74801879964873E-5,0.25,-2.23909185057896E-6,-1.58689480730692E-5,-2.32023920640228E-6,2.99911,2.99911,-14564.473,-14543.056,51.1810354392362,18.3452836342549,0.6169718,0,0,0,4961,2.9942,-14553.7645,,,,,,,,,,,,,,,,,13.400279,,,,,,2.99911,,,,
,2827942.13,2.9996592,-13745.2005,-1.98536354787669E-5,6.21190138070364E-7,1,0.999253354069792,40.0298881530762,1.98033824300792,9.28000226616859,-0.000218340663480919,-6.27973534198892E-5,0.25,-2.01160279841986E-6,-1.97358591993331E-5,-2.11529162431382E-6,2.9994748,2.9998436,-13755.625,-13734.776,51.647667665217,18.3435691816371,0.6169718,0,0,0,4961,2.9953,-13745.2005,,,,,,,,,,,,,,,,,13.400279,,,,,,2.9996592,,,,
,2827948.975,3.0002525,-13038.2415,-2.43340767060108E-5,3.33706605749418E-7,1,0.999253354069792,40.0298881530762,1.98035404148228,9.28000226616859,-0.000268438312594898,-7.23389631609266E-5,0.25,-2.05385100080207E-6,-2.41906944131636E-5,-2.18177310227753E-6,3.0002525,3.0002525,-13101.92,-12974.563,52.1596343453132,18.343851846925,0.62006895,0,0,0,4961,2.9948,-13038.2415,,,,,,,,,,,,,,,,,13.400279,,,,,,3.0002525,,,,
,2827957.285,2.99824145,-12155.185,-2.86552006091658E-5,5.64279194453504E-7,1,0.999253354069792,40.0298881530762,1.98029283165926,9.28000226616859,-0.000316508378165529,-8.27755536540245E-5,0.25,-2.20612421128329E-6,-2.84855353682084E-5,-2.35590331919664E-6,2.9979489,2.998534,-12165.895,-12144.475,51.5108826743516,18.344001183305,0.6108695,0,0,0,4961,2.9953,-12155.185,,,,,,,,,,,,,,,,,13.400279,,,,,,2.99824145,,,,
,2827964.57,2.9986405,-11371.3985,-3.18875892892013E-5,4.79391577134075E-7,1,0.999253354069792,40.0298881530762,1.98027463271174,9.28000226616859,-0.000352180492515323,-9.21382403102182E-5,0.25,-2.45967273572464E-6,-3.16967892318966E-5,-2.62432860696226E-6,2.9978964,2.9993846,-11427.658,-11315.139,51.7469344871593,18.3445282493712,0.6169718,0,0,0,4961,2.9951,-11371.3985,,,,,,,,,,,,,,,,,12.644608,,,,,,2.9986405,,,,
,2827971.93,2.9988127,-10596.8185,-3.6346721480191E-5,4.16956804227947E-7,1,0.999253354069792,40.0298881530762,1.98037387799687,9.29000187665224,-0.000401935221966413,-0.000102196126679074,0.25,-2.5534572466183E-6,-3.61284508828075E-5,-2.74029184007223E-6,2.9980848,2.9995406,-10658.997,-10534.64,51.3232918297362,18.3454402029589,0.62006895,0,0,0,4961,2.9956,-10596.8185,,,,,,,,,,,,,,,,,12.644608,,,,,,2.9988127,,,,
,2827980.405,2.99864105,-9713.572,-4.09658075999279E-5,5.36882690979682E-7,1,0.999253354069792,40.0298881530762,1.98023654350706,9.29000187665224,-0.00045470422376949,-0.000105479254750183,0.25,-2.01551339036943E-6,-4.07217671542794E-5,-2.22811938419458E-6,2.9977403,2.9995418,-9724.468,-9702.676,51.6812776915439,18.3420701920891,0.610839,0,0,0,4961,2.9953,-9713.572,,,,,,,,,,,,,,,,,13.400279,,,,,,2.99864105,,,,
,2827986.14,2.99810315,-9100.6325,-4.38067169795184E-5,3.6749439880997E-7,1,0.999253354069792,40.0298881530762,1.98025756567858,9.28000226616859,-0.00048550041885827,-0.00011676938025776,0.25,-2.51262121858773E-6,-4.3541777562805E-5,-2.73583053987631E-6,2.9973717,2.9988346,-9153.794,-9047.471,51.7938321983132,18.3419648332833,0.6169718,0,0,0,4961,2.99645,-9100.6325,,,,,,,,,,,,,,,,,13.400279,,,,,,2.99810315,,,,
,2827992.835,2.9975612,-8391.2335,-4.73925633626274E-5,4.57392819981028E-7,1,0.999253354069792,40.0298881530762,1.98029669725072,9.28000226616859,-0.000526276953370458,-0.000120493005943758,0.25,-2.2001474401028E-6,-4.71062418507298E-5,-2.44199303581583E-6,2.9972765,2.9978459,-8454.82,-8327.647,51.8547992228132,18.3415985613653,0.6108695,0,0,0,4961,2.9959,-8391.2335,,,,,,,,,,,,,,,,,12.644608,,,,,,2.9975612,,,,
,2828000.19,2.9979227,-7612.5175,-5.00170479555172E-5,4.96266698563696E-7,1,0.999253354069792,40.0298881530762,1.98036450014247,9.28000226616859,-0.000556556761715174,-0.000120797941608938,0.25,-1.75651160074226E-6,-4.97150430633482E-5,-2.01204766600498E-6,2.9979227,2.9979227,-7623.038,-7601.997,51.7555324008709,18.3442384205629,0.6169718,0,0,0,4961,2.99595,-7612.5175,,,,,,,,,,,,,,,,,13.022443,,,,,,2.9979227,,,,
,2828006.74,2.9981283,-6912.8865,-5.4290355169252E-5,2.48886085097122E-7,1,0.999253354069792,40.0298881530762,1.98031714102453,9.28000226616859,-0.000603517544502587,-0.000134128420054162,0.25,-2.17904023011243E-6,-5.39583913191564E-5,-2.45191086753378E-6,2.9978771,2.9983795,-6966.142,-6859.631,51.8399482809478,18.3423962690215,0.6169718,0,0,0,4961,2.9971,-6912.8865,,,,,,,,,,,,,,,,,13.778115,,,,,,2.9981283,,,,
,2828014.15,2.99750985,-6135.5795,-5.82905274512922E-5,6.76926161332867E-7,1,0.999253354069792,40.0298881530762,1.98028478573524,9.29000187665224,-0.000648572713233807,-0.000140492934350941,0.25,-2.02960024730354E-6,-5.79325773502029E-5,-2.32098695303155E-6,2.9975009,2.9975188,-6202.733,-6068.426,51.8555808513324,18.3412495209299,0.6108695,0,0,0,4961,2.9976,-6135.5795,,,,,,,,,,,,,,,,,12.644608,,,,,,2.99750985,,,,
,2828023.085,2.99828395,-5179.162,-6.15695961112963E-5,3.12827999670355E-7,1,0.999253354069792,40.0298881530762,1.98031795006465,9.28000226616859,-0.000684375772401727,-0.000151983470135599,0.25,-2.46906330847795E-6,-6.11858821499331E-5,-2.77049494984977E-6,2.9980187,2.9985492,-5189.682,-5168.642,51.7195774889862,18.3414146925021,0.6108695,0,0,0,4961,2.99725,-5179.162,,,,,,,,,,,,,,,,,13.400279,,,,,,2.99828395,,,,
,2828030.455,2.9976628,-4411.715,-6.50415666467979E-5,5.81619158669868E-7,1,0.999253354069792,40.0298881530762,1.98025462637616,9.28000226616859,-0.000724099480497336,-0.000153943361911609,0.25,-2.02253994048815E-6,-6.46359925839464E-5,-2.34086074987215E-6,2.9976628,2.9976628,-4422.141,-4401.289,51.8516727087362,18.344327734577,0.6231661,0,0,0,4961,2.9967,-4411.715,,,,,,,,,,,,,,,,,12.644608,,,,,,2.9976628,,,,
,2828037.39,2.9987619,-3657.1325,-6.77543809039025E-5,4.51505114527056E-7,1,0.999253354069792,40.0298881530762,1.98027942389518,9.28000226616859,-0.000754513039673088,-0.000159034406260571,0.25,-1.99217476819548E-6,-6.73292940668127E-5,-2.32082973534165E-6,2.9987619,2.9987619,-3667.184,-3647.081,51.6609553500439,18.3404088799171,0.6169718,0,0,0,4961,2.998,-3657.1325,,,,,,,,,,,,,,,,,13.400279,,,,,,2.9987619,,,,
,2828044.065,2.9983691,-2960.971,-7.0575889001621E-5,4.12833764656549E-7,1,0.999253354069792,40.0298881530762,1.98031028431733,9.28000226616859,-0.000785348502596675,-0.000168782072018349,0.25,-2.35798521673672E-6,-7.01287738814916E-5,-2.69518138175843E-6,2.9977098,2.9990284,-3025.495,-2896.447,51.4819624191401,18.3419842142953,0.6108695,0,0,0,4961,2.9971,-2960.971,,,,,,,,,,,,,,,,,13.400279,,,,,,2.9983691,,,,
,2828051.665,2.9981925,-2124.297,-7.21241135394735E-5,5.16463726098356E-7,1,0.999253354069792,40.0298881530762,1.98035027818738,9.28000226616859,-0.000802996662111842,-0.000170026740329679,0.25,-2.19449227567776E-6,-7.16648943237483E-5,-2.53640456040649E-6,2.9981925,2.9981925,-2135.287,-2113.307,51.6468860366978,18.3430522165589,0.6169718,0,0,0,4961,2.99725,-2124.297,,,,,,,,,,,,,,,,,13.400279,,,,,,2.9981925,,,,
,2828057.9,2.99850045,-1445.318,-7.25560932187924E-5,5.14772211811192E-7,1,0.999253354069792,40.0298881530762,1.98026648782798,9.28000226616859,-0.000808406820087445,-0.000167352523263302,0.25,-1.8819497301208E-6,-7.20931722976725E-5,-2.22486647008332E-6,2.9981959,2.998805,-1514.446,-1376.19,51.7672568286593,18.3411761228575,0.6169718,0,0,0,4961,2.99855,-1445.318,,,,,,,,,,,,,,,,,12.644608,,,,,,2.99850045,,,,
,2828064.16,2.9986373,-765.4955,-6.9179146311095E-5,5.8156057109164E-7,1,0.999253354069792,40.0298881530762,1.98026674963065,9.28000226616859,-0.000769685666243518,-0.000165506581698214,0.25,-2.32836884346121E-6,-6.87329794389283E-5,-2.64928868524919E-6,2.9978859,2.9993887,-834.998,-695.993,51.975951643294,18.3422183094206,0.62006895,0,0,0,4961,2.99885,-765.4955,,,,,,,,,,,,,,,,,13.400279,,,,,,2.9986373,,,,
,2828070.995,2.9988033,-10.4405,-4.54679382218821E-5,5.67859608605476E-7,1,0.999253354069792,40.0298881530762,1.98021881187289,9.29000187665224,-0.00050452581444083,-0.000116125141642559,0.25,-2.18862183824402E-6,-4.51702851702091E-5,-2.39383711246281E-6,2.998349,2.9992576,-76.281,55.4,51.30922251639,18.3413118434318,0.6108695,0,0,0,4961,2.9983,-10.4405,,,,,,,,,,,,,,,,,13.400279,,,,,,2.9988033,,,,
,2828077.905,2.99718545,742.8325,2.02653032463551E-5,2.94324021931518E-7,1,0.999253354069792,40.0298881530762,1.98023510242032,9.29000187665224,0.000230156012030171,2.24458780142107E-5,0.25,-1.6439345434562E-6,2.01458632750158E-5,-1.53532495419916E-6,2.9962518,2.9981191,732.408,753.257,51.9243641610247,18.3395658124245,0.6169718,0,0,0,4961,2.99805,742.8325,,,,,,,,,,,,,,,,,13.400279,,,,,,2.99718545,,,,
,2828084.55,2.99793765,1442.5675,3.84294253307696E-5,4.24779821594355E-7,1,0.999253354069792,40.0298881530762,1.98021369999054,9.28000226616859,0.000433521545946519,5.88817953861523E-5,0.25,-1.66132241054777E-6,3.81972269357591E-5,-1.46307998375853E-6,2.9973211,2.9985542,1387.622,1497.513,51.5859190121978,18.3397256656724,0.6169718,0,0,0,4961,2.99735,1442.5675,,,,,,,,,,,,,,,,,13.400279,,,,,,2.99793765,,,,
,2828092.11,2.9976959,2216.0315,4.68592971058802E-5,5.34700923244001E-7,1,0.999253354069792,40.0298881530762,1.98029324584548,9.28000226616859,0.000528737520226383,7.13893123936973E-5,0.25,-2.06502443504573E-6,4.65784015379082E-5,-1.82091983212526E-6,2.9976959,2.9976959,2205.7,2226.363,51.7680384571786,18.3409685216028,0.6231661,0,0,0,4961,2.9969,2216.0315,,,,,,,,,,,,,,,,,13.022443,,,,,,2.9976959,,,,
,2828100.86,2.9978256,3063.038,5.20931977531964E-5,3.63169209289702E-7,1,0.999253354069792,40.0298881530762,1.98025241960416,9.28000226616859,0.000586554224168544,8.63519478503614E-5,0.25,-1.67449141816574E-6,5.1780525350668E-5,-1.40419237650608E-6,2.9978256,2.9978256,3053.644,3072.432,51.6953470048901,18.3416362853214,0.61700255,0,0,0,4961,2.99785,3063.038,,,,,,,,,,,,,,,,,13.400279,,,,,,2.9978256,,,,
,2828106.46,2.9983833,3625.548,5.30505101504916E-5,4.85835110884489E-7,1,0.999253354069792,40.0298881530762,1.98032817817473,9.28000226616859,0.000598524218126625,8.15821026212904E-5,0.25,-2.2756496020919E-6,5.27368600657511E-5,-1.99493220413035E-6,2.9983833,2.9983833,3565.906,3685.19,51.4061444527747,18.3418688972102,0.6139054,0,0,0,4961,2.9973,3625.548,,,,,,,,,,,,,,,,,12.644608,,,,,,2.9983833,,,,
,2828115.94,2.9983053,4585.26,5.21440554372002E-5,2.78896263503067E-7,1,0.999253354069792,40.0298881530762,1.9802963162279,9.28000226616859,0.000587423415711983,8.52015702689959E-5,0.25,-1.79282126474991E-6,5.18368789764781E-5,-1.5162561714612E-6,2.9974861,2.9991245,4564.691,4605.829,52.199497399794,18.3437024930603,0.62006895,0,0,0,4961,2.9989,4585.26,,,,,,,,,,,,,,,,,13.400279,,,,,,2.9983053,,,,
,2828123.515,2.999743,5348.199,5.099589851892E-5,4.56950676164666E-7,1,0.999253354069792,40.0298881530762,1.9802536593785,9.29000187665224,0.00057545229919984,7.80926869510269E-5,0.25,-2.22373828187623E-6,5.07006298117492E-5,-1.94775767721582E-6,2.999743,2.999743,5337.493,5358.905,51.6156208959285,18.341711603284,0.62006895,0,0,0,4961,2.9983,5348.199,,,,,,,,,,,,,,,,,12.644608,,,,,,2.999743,,,,
,2828130.8,2.9989066,6100.243,4.88571381170833E-5,6.16180221685202E-7,1,0.999253354069792,40.0298881530762,1.98029758342319,9.28000226616859,0.000550179597645654,8.13678074234378E-5,0.25,-1.5486402300679E-6,4.85739094009603E-5,-1.28516411132722E-6,2.9989066,2.9989066,6080.05,6120.436,51.6023332111016,18.3412593973604,0.61700255,0,0,0,4961,2.99705,6100.243,,,,,,,,,,,,,,,,,13.400279,,,,,,2.9989066,,,,
,2828137.155,2.9994186,6735.821,4.71672745393106E-5,4.54055799111199E-7,1,0.999253354069792,40.0298881530762,1.98029827135923,9.28000226616859,0.000531296728847213,7.78860581514608E-5,0.25,-1.55720561009436E-6,4.68963943895302E-5,-1.30035900573862E-6,2.9988389,2.9999983,6674.583,6797.059,51.7946138268324,18.3420976278123,0.62006895,0,0,0,4961,2.9978,6735.821,,,,,,,,,,,,,,,,,13.400279,,,,,,2.9994186,,,,
,2828145.7,2.999347,7615.692,4.47083815305007E-5,5.61145097419819E-7,1,0.999253354069792,40.0298881530762,1.98018579541941,9.28000226616859,0.000504682999100451,6.78608082464484E-5,0.25,-2.01171142345826E-6,4.44574770556085E-5,-1.76232874268525E-6,2.999347,2.999347,7604.985,7626.399,51.7055081756401,18.3415322509054,0.6169718,0,0,0,4961,2.99655,7615.692,,,,,,,,,,,,,,,,,12.644608,,,,,,2.999347,,,,
,2828152.22,2.9992032,8287.615,4.18314764252562E-5,3.15955631230882E-7,1,0.999253354069792,40.0298881530762,1.98027909184142,9.28000226616859,0.00047324774847451,5.80018665862439E-5,0.25,-2.37535426434873E-6,4.16015926277834E-5,-2.13718186564344E-6,2.9987893,2.9996171,8222.245,8352.985,51.7000367760055,18.3419473020771,0.6139054,0,0,0,4961,2.9972,8287.615,,,,,,,,,,,,,,,,,12.644608,,,,,,2.9992032,,,,
,2828159.445,2.9995611,9034.303,3.88256839345085E-5,4.34438164316174E-7,1,0.999253354069792,40.0298881530762,1.98026489356761,9.28000226616859,0.000438333232663816,5.90041932919821E-5,0.25,-1.74542808668169E-6,3.86122056130536E-5,-1.52499151985215E-6,2.9995611,2.9995611,9034.303,9034.303,51.5499641003131,18.3410369816042,0.6169718,0,0,0,4961,2.997,9034.303,,,,,,,,,,,,,,,,,12.644608,,,,,,2.9995611,,,,
,2828167.94,3.0003073,9907.031,3.60905945579171E-5,4.61651330809407E-7,1,0.999253354069792,40.0298881530762,1.98027225864219,9.28000226616859,0.00040920604923229,4.53342513979077E-5,0.25,-2.47462442378494E-6,3.58994410670319E-5,-2.26266660204843E-6,3.0003073,3.0003073,9907.031,9907.031,51.7453712301209,18.3417893738916,0.6169718,0,0,0,4961,2.9948,9907.031,,,,,,,,,,,,,,,,,13.778115,,,,,,3.0003073,,,,
,2828175.915,3.000779,10730.4515,3.19968093868556E-5,4.54459090917321E-7,1,0.999253354069792,40.0298881530762,1.98045589350758,9.28000226616859,0.000362456443619054,4.23666542189362E-5,0.25,-2.00231163552093E-6,3.18285567164957E-5,-1.81367328443111E-6,3.0005078,3.0010502,10720.026,10740.877,51.6648634926401,18.3436215062018,0.6169718,0,0,0,4961,2.9972,10730.4515,,,,,,,,,,,,,,,,,13.400279,,,,,,3.000779,,,,
,2828182.78,3.0010293,11443.6985,2.98848956162955E-5,5.54831558999354E-7,1,0.999253354069792,40.0298881530762,1.98017370340274,9.28000226616859,0.000339896833869108,3.1883242639478E-5,0.25,-2.55778854753774E-6,2.97334666164148E-5,-2.37633055599902E-6,3.0010293,3.0010293,11423.691,11463.706,51.6812776915439,18.3400493347914,0.6169718,0,0,0,4961,2.99605,11443.6985,,,,,,,,,,,,,,,,,13.778115,,,,,,3.0010293,,,,
,2828190.835,3.0017138,12278.765,2.54022781071851E-5,2.88831080598418E-7,1,0.999253354069792,40.0298881530762,1.98033905487115,9.29000187665224,0.000288104508554497,3.18303683286214E-5,0.25,-1.75386567502548E-6,2.52731132651647E-5,-1.60052824676694E-6,3.0017138,3.0017138,12258.289,12299.241,51.2013577807362,18.3401875937651,0.6047672,0,0,0,4961,2.9979,12278.765,,,,,,,,,,,,,,,,,13.400279,,,,,,3.0017138,,,,
,2828199.365,3.0013344,13164.9235,2.18804329242145E-5,4.35357704212459E-7,1,0.999253354069792,40.0298881530762,1.98028395191937,9.28000226616859,0.000249120977771805,2.21882932528897E-5,0.25,-1.97903683693874E-6,2.17736261215738E-5,-1.84313690812351E-6,3.0013344,3.0013344,13155.248,13174.599,51.6554839504093,18.3403327469925,0.6169718,0,0,0,4961,2.9968,13164.9235,,,,,,,,,,,,,,,,,13.400279,,,,,,3.0013344,,,,
,2828205.94,3.00152025,13841.9255,1.87751827281577E-5,3.62592275129E-7,1,0.999253354069792,40.0298881530762,1.98020027626768,9.28000226616859,0.000213079201517553,2.28609378164356E-5,0.25,-1.35799248510254E-6,1.86827679874912E-5,-1.24238044936627E-6,3.000967,3.0020735,13776.651,13907.2,51.9634455869863,18.3388060653991,0.61396665,0,0,0,4961,2.99625,13841.9255,,,,,,,,,,,,,,,,,13.400279,,,,,,3.00152025,,,,
,2828211.935,3.00094045,14460.4995,1.55973998022348E-5,3.89485119167583E-7,1,0.999253354069792,40.0298881530762,1.98028122333504,9.28000226616859,0.000179596060504701,4.83301053135891E-6,0.25,-2.39279674930003E-6,1.55288883682346E-5,-2.28944106183935E-6,3.000639,3.0012419,14398.98,14522.019,51.6453227796593,18.338943606494,0.6169718,0,0,0,4961,2.99555,14460.4995,,,,,,,,,,,,,,,,,13.400279,,,,,,3.00094045,,,,
,2828217.89,3.00194215,15082.644,1.27245469682517E-5,5.59224131362151E-7,1,0.999253354069792,40.0298881530762,1.9802634540797,9.29000187665224,0.000146427877617503,4.47715564285735E-6,0.25,-1.90497350767843E-6,1.26691760138603E-5,-1.8204482436402E-6,3.0014179,3.0024664,15019.811,15145.477,51.7047265471209,18.3398371294221,0.6108695,0,0,0,4961,2.99505,15082.644,,,,,,,,,,,,,,,,,13.778115,,,,,,3.00194215,,,,
,2828225.86,3.0017649,15897.4195,8.70104408454363E-6,3.48903326099135E-7,1,0.999253354069792,40.0298881530762,1.98035417260267,9.28000226616859,0.000101215091177529,-2.87111043957972E-6,0.25,-1.83262487912004E-6,8.66703725532642E-6,-1.77169304077278E-6,3.001756,3.0017738,15835.244,15959.595,51.8805929639478,18.3404986106941,0.62006895,0,0,0,4961,2.99505,15897.4195,,,,,,,,,,,,,,,,,13.400279,,,,,,3.0017649,,,,
,2828234.05,3.0032151,16754.179,5.13643225450534E-6,3.83744886717084E-7,1,0.999253354069792,40.0298881530762,1.9801947023479,9.28000226616859,6.13972102336813E-5,-1.07811144444524E-5,0.25,-1.89307705126341E-6,5.12167600362119E-6,-1.85277037821118E-6,3.0032151,3.0032151,16733.516,16774.842,51.7883607986786,18.3430329983554,0.6108695,0,0,0,4961,2.99555,16754.179,,,,,,,,,,,,,,,,,12.644608,,,,,,3.0032151,,,,
,2828240.375,3.0016,17407.9725,1.6878802479974E-6,3.11516908055152E-7,1,0.999253354069792,40.0298881530762,1.9801479695155,9.28000226616859,2.32913282392261E-5,-2.07236768909079E-5,0.25,-2.15544953279907E-6,1.69239502674306E-6,-2.13447768351632E-6,3.0016,3.0016,17397.736,17418.209,51.7867975416401,18.3369039387259,0.6169718,0,0,0,4961,2.9934,17407.9725,,,,,,,,,,,,,,,,,13.400279,,,,,,3.0016,,,,
,2828247.68,3.0019226,18154.093,-2.81660200931733E-6,5.81761314291628E-7,1,0.999253354069792,40.0298881530762,1.98026753209255,9.29000187665224,-2.74838996101502E-5,-2.82264683258353E-5,0.25,-2.0080094089666E-6,-2.79048416123779E-6,-2.0151834034494E-6,3.0019226,3.0019226,18143.291,18164.895,51.6859674626593,18.3393928607876,0.6169718,0,0,0,4961,2.9953,18154.093,,,,,,,,,,,,,,,,,12.644608,,,,,,3.0019226,,,,
,2828254.37,3.0034181,18863.302,-5.91480094483806E-6,7.9214315800912E-7,1,0.999253354069792,40.0298881530762,1.98022090573994,9.29000187665224,-6.38431751823921E-5,-2.54961712539842E-5,0.25,-1.20220244183184E-6,-5.87860092474039E-6,-1.23253312259977E-6,3.0030971,3.0037391,18807.887,18918.717,51.8266605961209,18.3383265977202,0.6169718,0,0,0,4961,2.9942,18863.302,,,,,,,,,,,,,,,,,13.400279,,,,,,3.0034181,,,,
,2828261.945,3.00285885,19644.7865,-1.06202644720966E-5,4.43795999910228E-7,1,0.999253354069792,40.0298881530762,1.98024718163031,9.29000187665224,-0.00011463145952479,-4.58410972247419E-5,0.25,-2.16322145726578E-6,-1.05559255144912E-5,-2.21836686695043E-6,3.001806,3.0039117,19624.893,19664.68,51.3850404827554,18.3386360086746,0.6169718,0,0,0,4961,2.992,19644.7865,,,,,,,,,,,,,,,,,12.644608,,,,,,3.00285885,,,,
,2828284.2,3.0015023,19999.1055,-1.16826110298571E-5,3.92609527942266E-7,1,0.999253354069792,40.0298881530762,1.98030084076575,9.28000226616859,-0.000127081853177143,-4.5047017200162E-5,0.25,-1.89912116096465E-6,-1.16151587026038E-5,-1.9624236410179E-6,3.0014837,3.0015209,19998.793,19999.418,51.7023816615632,18.3406558534222,0.6047672,0,0,0,4929,2.9932,19999.1055,,,,,,,,,,,,,,,,,13.400279,,,,,,3.0015023,,,,