File: inst/extdata/sample5.dat
[Header]
; VSM Data File (default extension .dat)
; Copyright (c) 2003, Quantum Design, Inc. All rights reserved.
TITLE,TS100928SI1, FEPC(200NM)/SI, DEPOSITED AT 230C, HYSTERSIS LOOP AT 100K
FILEOPENTIME,15784175.91,03/07/2011,12:17 pm
BYAPP,VSM,1.0,1.0
INFO,PPMS VSM Option Release 1.3.6 Build 0,APPNAME
INFO,171,COIL_SERIAL_NUMBER
INFO,0,MOMENT_UNITS
INFO,FePc(200nm)/Si,SAMPLE_MATERIAL
INFO,TS100928Si1, FePc(200nm)/Si, Deposited at 230C,SAMPLE_COMMENT
INFO,,SAMPLE_MASS
INFO,,SAMPLE_VOLUME
INFO,,SAMPLE_MOLECULAR_WEIGHT
INFO,4x10mm,SAMPLE_SIZE
INFO,,SAMPLE_SHAPE
INFO,34.35,SAMPLE_OFFSET
DATATYPE,COMMENT,1
DATATYPE,TIME,2
STARTUPAXIS,X,2
STARTUPAXIS,Y1,5
[Data]
Comment,Time Stamp (sec),Temperature (K),Magnetic Field (Oe),Moment (emu),M. Std. Err. (emu),Transport Action,Averaging Time (sec),Frequency (Hz),Peak Amplitude (mm),Center Position (mm),Coil Signal' (mV),Coil Signal" (mV),Range (mV),M. Quad. Signal (emu),M. Raw' (emu),M. Raw" (emu),Min. Temperature (K),Max. Temperature (K),Min. Field (Oe),Max. Field (Oe),Mass (grams),Motor Lag (deg),Pressure (Torr),VSM Status (code),Motor Status (code),Measure Status (code),PPMS Status (code),System Temp. (K),System Field (Oe),Sample Position (deg),Bridge 1 Resistance (ohms),Bridge 1 Excitation (에),Bridge 2 Resistance (ohms),Bridge 2 Excitation (에),Bridge 3 Resistance (ohms),Bridge 3 Excitation (에),Bridge 4 Resistance (ohms),Bridge 4 Excitation (에),Signal 1 Vin (V),Signal 2 Vin (V),Digital Inputs (code),Drive 1 Iout (mA),Drive 1 Ipower (W),Drive 2 Iout (mA),Drive 2 Ipower (W),Pressure (),Map 20 (),Map 21 (),Map 22 (),Map 23 (),Map 24 (),Map 25 (),Map 26 (),Map 27 (),Map 28 (),Map 29 ()
,15784215.85,99.9891434,9999.681,-3.20420667907499E-5,1.75532721000979E-9,1,1.99338665628444,40.1327056884766,2.00199390947736,7.21000373363495,-0.000370087856284124,-4.88888671618092E-5,0.25,-1.31352648021354E-6,-3.22023479718579E-5,-1.41975374843266E-6,99.9886246,99.9896622,9999.174,10000.188,53.3367668952749,17.5873122525913,51.04141995,0,0,0,4417,99.7023,9999.681,,,,,,,,,,,,,,,,,73.476204,,,,,,99.9891434,,,,
,15784227.735,99.9895706,9979.217,-3.18715974587458E-5,1.10518441113098E-9,1,1.99338665628444,40.1327056884766,2.00202070289372,7.21000373363495,-0.000368007651733831,-4.9910301090641E-5,0.25,-1.41702385497902E-6,-3.20306822688243E-5,-1.52325334518695E-6,99.9895706,99.9895706,9974.814,9983.62,53.5204495972941,17.5900021539334,51.04141995,0,0,0,4449,99.70315,9979.217,,,,,,,,,,,,,,,,,73.098366,,,,,,99.9895706,,,,
,15784228.4,99.989357,9970.282,-3.28218924263646E-5,1.00437287880402E-9,1,1.99338665628444,40.1327056884766,2.00206770515807,7.21000373363495,-0.000378811920155397,-5.33534507257648E-5,0.25,-1.62780049823129E-6,-3.2985196757692E-5,-1.73806311050855E-6,99.9891434,99.9895706,9956.944,9983.62,53.7494667534288,17.5904632824662,51.04141995,0,0,0,4449,99.70295,9970.282,,,,,,,,,,,,,,,,,73.476204,,,,,,99.989357,,,,
,15784229.885,99.98960495,9932.7135,-3.18791436477432E-5,1.71930562199771E-9,1,1.99338665628444,40.1327056884766,2.00202728773303,7.21000373363495,-0.000368047058287289,-5.04616844196471E-5,0.25,-1.4638823480354E-6,-3.20381192843681E-5,-1.57038020590315E-6,99.9891434,99.9900665,9908.483,9956.944,53.8088705208903,17.5921882314143,51.04141995,0,0,0,4449,99.70325,9932.7135,,,,,,,,,,,,,,,,,73.098366,,,,,,99.98960495,,,,
,15784231.8,99.98943325,9881.246,-3.16935305395648E-5,1.70905732523179E-9,1,1.99338665628444,40.1327056884766,2.00204206571654,7.21000373363495,-0.000365915389680751,-5.00724971535757E-5,0.25,-1.44709099758613E-6,-3.18516009763439E-5,-1.5529367525758E-6,99.9888,99.9900665,9854.009,9908.483,53.7713523519672,17.5920433978522,51.04141995,0,0,0,4449,99.7002,9881.246,,,,,,,,,,,,,,,,,73.098366,,,,,,99.98943325,,,,
,15784233.79,99.9889221,9829.682,-3.14413829688101E-5,1.19081513540762E-9,1,1.99338665628444,40.1327056884766,2.00202646605163,7.21000373363495,-0.000362887589997985,-5.09300650772701E-5,0.25,-1.54393547314657E-6,-3.15978552394732E-5,-1.64950338908872E-6,99.9888,99.9890442,9805.355,9854.009,53.7987093501403,17.5918431541482,50.5315399,0,0,0,4449,99.69825,9829.682,,,,,,,,,,,,,,,,,73.098366,,,,,,99.9889221,,,,
,15784235.795,99.98942565,9778.4925,-3.11064406059063E-5,1.74610670072294E-9,1,1.99338665628444,40.1327056884766,2.00204240952015,7.20000365749001,-0.000358994659000504,-5.07177375835554E-5,0.25,-1.55593580021477E-6,-3.12611559428524E-5,-1.66052768266347E-6,99.9890442,99.9898071,9751.63,9805.355,53.8088705208903,17.5916680635514,50.5315399,0,0,0,4449,99.6997,9778.4925,,,,,,,,,,,,,,,,,73.098366,,,,,,99.98942565,,,,
,15784237.79,99.9889183,9727.4925,-3.12907947397084E-5,1.85667657696216E-9,1,1.99338665628444,40.1327056884766,2.00203772267926,7.20000365749001,-0.000361221935121304,-4.99090340280599E-5,0.25,-1.46948195835438E-6,-3.14467231199381E-5,-1.57420558706022E-6,99.9880295,99.9898071,9703.355,9751.63,53.6822467007749,17.5927914500039,51.04141995,0,0,0,4449,99.7012,9727.4925,,,,,,,,,,,,,,,,,73.098366,,,,,,99.9889183,,,,
,15784239.775,99.9885483,9676.117,-3.12808299161334E-5,1.84932563656649E-9,1,1.99338665628444,40.1327056884766,2.00204261860755,7.21000373363495,-0.000360748082589309,-5.38623810149389E-5,0.25,-1.8113727888681E-6,-3.14356445343884E-5,-1.91782092012911E-6,99.9880295,99.9890671,9648.879,9703.355,53.8119970349672,17.5922513309537,51.5513,0,0,0,4449,99.70315,9676.117,,,,,,,,,,,,,,,,,73.098366,,,,,,99.9885483,,,,
,15784241.805,99.9886284,9623.0505,-3.08038906517776E-5,1.95973037744373E-9,1,1.99338665628444,40.1327056884766,2.00197765471165,7.21000373363495,-0.000355670023720928,-4.82552798894718E-5,0.25,-1.37107455854968E-6,-3.09576250819424E-5,-1.47378584231978E-6,99.9881897,99.9890671,9597.222,9648.879,53.7236730122941,17.5929571623757,51.5513,0,0,0,4449,99.7046,9623.0505,,,,,,,,,,,,,,,,,73.098366,,,,,,99.9886284,,,,
,15784243.78,99.9886322,9573.5535,-3.05514209998817E-5,1.78829347345993E-9,1,1.99338665628444,40.1327056884766,2.00202837752456,7.21000373363495,-0.000352720233552484,-4.83398910222139E-5,0.25,-1.40114455370879E-6,-3.07037651730893E-5,-1.50322962967204E-6,99.9881897,99.9890747,9549.885,9597.222,53.7432137252749,17.5938103822031,51.2950611,0,0,0,4449,99.70525,9573.5535,,,,,,,,,,,,,,,,,72.34269,,,,,,99.9886322,,,,
,15784245.74,99.9894142,9523.869,-3.0478123335456E-5,1.30173055899661E-9,1,1.99338665628444,40.1327056884766,2.00197859701986,7.21000373363495,-0.000351737227536615,-4.96376509012529E-5,0.25,-1.51982712510448E-6,-3.06297204204581E-5,-1.62229712731216E-6,99.9890747,99.9897537,9497.853,9549.885,53.6009573347749,17.5928841869298,51.0388222,0,0,0,4449,99.7058,9523.869,,,,,,,,,,,,,,,,,73.098366,,,,,,99.9894142,,,,
,15784247.75,99.98898315,9471.6455,-3.01994969892954E-5,1.11953062491029E-9,1,1.99338665628444,40.1327056884766,2.00197723290542,7.21000373363495,-0.000348314185475416,-5.14710528775764E-5,0.25,-1.70322170373486E-6,-3.03490935559922E-5,-1.80577068298455E-6,99.9882126,99.9897537,9445.438,9497.853,53.6884997289287,17.5941832655836,50.78518105,0,0,0,4449,99.7065,9471.6455,,,,,,,,,,,,,,,,,73.476204,,,,,,99.98898315,,,,
,15784249.765,99.98871615,9422.0535,-3.0477784282458E-5,1.69261218713593E-9,1,1.99338665628444,40.1327056884766,2.00199712365812,7.21000373363495,-0.000351563007370004,-5.1551433236919E-5,0.25,-1.68488968280751E-6,-3.06288626257765E-5,-1.78821407293693E-6,99.9882126,99.9892197,9398.669,9445.438,53.7830767797557,17.5932582960708,50.78518105,0,0,0,4449,99.7064,9422.0535,,,,,,,,,,,,,,,,,73.476204,,,,,,99.98871615,,,,
,15784251.75,99.9890442,9373.0275,-3.01918633104836E-5,1.32265423042634E-9,1,1.99338665628444,40.1327056884766,2.00196349395723,7.20000365749001,-0.000348073943429642,-5.31108667491244E-5,0.25,-1.84538325264815E-6,-3.03409738725519E-5,-1.94864732894348E-6,99.9888687,99.9892197,9347.386,9398.669,53.6603611022364,17.5938462407579,51.2950611,0,0,0,4449,99.7063,9373.0275,,,,,,,,,,,,,,,,,73.098366,,,,,,99.9890442,,,,
,15784253.72,99.9891052,9321.839,-3.02180234462994E-5,1.20064055449746E-9,1,1.99338665628444,40.1327056884766,2.00197297712737,7.20000365749001,-0.000348743184188038,-4.91175884564573E-5,0.25,-1.49853286951792E-6,-3.03683443138808E-5,-1.60010205576401E-6,99.9888687,99.9893417,9296.292,9347.386,53.851860089448,17.5941377786788,51.2950611,0,0,0,4449,99.70765,9321.839,,,,,,,,,,,,,,,,,73.476204,,,,,,99.9891052,,,,
,15784255.75,99.98971935,9270.745,-2.95446903136831E-5,1.39937870957141E-9,1,1.99338665628444,40.1327056884766,2.00202392738655,7.20000365749001,-0.000341181382183948,-4.58102145184708E-5,0.25,-1.27415610709194E-6,-2.96922523861346E-5,-1.37248703437685E-6,99.9893417,99.990097,9245.198,9296.292,53.8252847197942,17.5946954274481,51.2950611,0,0,0,4449,99.70785,9270.745,,,,,,,,,,,,,,,,,73.098366,,,,,,99.98971935,,,,
,15784257.755,99.9903183,9222.47,-2.95827341844433E-5,1.78107905547901E-9,1,1.99338665628444,40.1327056884766,2.00199301984829,7.20000365749001,-0.000341288009919387,-4.94827079553006E-5,0.25,-1.58754381326511E-6,-2.97295135420836E-5,-1.68760731523618E-6,99.990097,99.9905396,9199.742,9245.198,53.5798533647557,17.5952694241463,51.04141995,0,0,0,4449,99.70615,9222.47,,,,,,,,,,,,,,,,,72.34269,,,,,,99.9903183,,,,
,15784259.725,99.99105835,9174.946,-2.91923833819638E-5,1.80761532670294E-9,1,1.99338665628444,40.1327056884766,2.0020146551786,7.20000365749001,-0.000336678656777844,-5.00385493063568E-5,0.25,-1.67081193853939E-6,-2.93368987359444E-5,-1.77009511470764E-6,99.9905396,99.9915771,9150.15,9199.742,53.7541565245441,17.5947276813161,51.04141995,0,0,0,4449,99.70535,9174.946,,,,,,,,,,,,,,,,,73.476204,,,,,,99.99105835,,,,
,15784261.72,99.99083705,9127.3255,-2.91796360584967E-5,5.24120809909841E-10,1,1.99338665628444,40.1327056884766,2.00201003064694,7.20000365749001,-0.00033651497351162,-5.01917839066227E-5,0.25,-1.68518910158471E-6,-2.9324038507973E-5,-1.78451200160869E-6,99.990097,99.9915771,9104.501,9150.15,53.9081373428326,17.5945924863457,51.2950611,0,0,0,4449,99.70455,9127.3255,,,,,,,,,,,,,,,,,73.476204,,,,,,99.99083705,,,,
,15784263.695,99.99033735,9078.955,-2.91310162418953E-5,1.78125199576784E-9,1,1.99338665628444,40.1327056884766,2.00204163767829,7.21000373363495,-0.000336035784631096,-4.92661798255272E-5,0.25,-1.60968573248461E-6,-2.92754023072338E-5,-1.70847408007323E-6,99.990097,99.9905777,9053.409,9104.501,53.6642692448326,17.5947136505841,51.2950611,0,0,0,4449,99.705,9078.955,,,,,,,,,,,,,,,,,73.098366,,,,,,99.99033735,,,,
,15784265.695,99.99085235,9028.7075,-2.90676378579816E-5,1.68371045373263E-9,1,1.99338665628444,40.1327056884766,2.00203134805959,7.20000365749001,-0.000335338087019589,-4.87713339656205E-5,0.25,-1.57276186367266E-6,-2.92118107130236E-5,-1.6711689193545E-6,99.9905777,99.991127,9004.006,9053.409,53.7439953537942,17.5954441089424,51.5513,0,0,0,4449,99.7047,9028.7075,,,,,,,,,,,,,,,,,73.098366,,,,,,99.99085235,,,,
,15784267.72,99.99134065,8981.6515,-2.90300670639745E-5,1.8699839209089E-9,1,1.99338665628444,40.1327056884766,2.00201009977588,7.21000373363495,-0.000334720634380412,-5.06997634827098E-5,0.25,-1.74254564955323E-6,-2.91735159816374E-5,-1.84171277542827E-6,99.991127,99.9915543,8959.297,9004.006,53.7260178978518,17.5953774728528,51.04141995,0,0,0,4449,99.70345,8981.6515,,,,,,,,,,,,,,,,,73.476204,,,,,,99.99134065,,,,
,15784269.695,99.9908371,8934.9715,-2.90612288992462E-5,1.04901679406678E-9,1,1.99338665628444,40.1327056884766,2.00205834246018,7.21000373363495,-0.000335412591032939,-4.71712414449325E-5,0.25,-1.43526281819332E-6,-2.92057919445672E-5,-1.53295308895078E-6,99.9901199,99.9915543,8910.646,8959.297,53.6744304155826,17.5958487075007,51.04141995,0,0,0,4449,99.7049,8934.9715,,,,,,,,,,,,,,,,,73.098366,,,,,,99.9908371,,,,
,15784271.695,99.99022675,8885.9435,-2.84551545141514E-5,1.56017943180366E-9,1,1.99338665628444,40.1327056884766,2.00203869866208,7.21000373363495,-0.00032803224331244,-5.0403854223353E-5,0.25,-1.76905303303286E-6,-2.85955702098818E-5,-1.86657532955868E-6,99.9901199,99.9903336,8861.241,8910.646,53.8260663483134,17.5956673000677,51.5513,0,0,0,4449,99.705,8885.9435,,,,,,,,,,,,,,,,,72.720528,,,,,,99.99022675,,,,
,15784273.69,99.9908104,8839.451,-2.84010535814332E-5,1.49341651971253E-9,1,1.99338665628444,40.1327056884766,2.00205655977651,7.21000373363495,-0.000327263895365576,-5.19359436911894E-5,0.25,-1.90606419088309E-6,-2.85407628432025E-5,-2.00412602421452E-6,99.9903336,99.9912872,8817.661,8861.241,53.9417473691596,17.5947285452645,51.5513,0,0,0,4449,99.7043,8839.451,,,,,,,,,,,,,,,,,72.34269,,,,,,99.9908104,,,,
,15784275.69,99.99145125,8793.4285,-2.84529284696803E-5,1.23281164456395E-9,1,1.99338665628444,40.1327056884766,2.00205814376482,7.20000365749001,-0.000327960201782313,-5.09457958732555E-5,0.25,-1.81595100521374E-6,-2.85931816821029E-5,-1.91371538244172E-6,99.9912872,99.9916153,8769.196,8817.661,53.8276296053519,17.5962370473626,51.5513,0,0,0,4449,99.70475,8793.4285,,,,,,,,,,,,,,,,,73.098366,,,,,,99.99145125,,,,